<?xml version="1.0" encoding="utf-8"?>
<!-- =================================================================================== -->
<!-- |    This document was autogenerated by xacro from em_3905_barebones.urdf.xacro   | -->
<!-- |    EDITING THIS FILE BY HAND IS NOT RECOMMENDED                                 | -->
<!-- =================================================================================== -->
<robot name="em_3905">
  <material name="chassis_mat">
    <color rgba="0.5 0.5 0.5 1"/>
  </material>
  <material name="tire_mat">
    <color rgba="0 0 0 1"/>
  </material>

  <!-- base_link must have geometry so that its axes can be displayed in
       rviz. -->
  <link name="base_link"/>

  <!-- Chassis -->
  <link name="chassis">
    <visual>
      <origin xyz="0 0 -0.01"/>
      <geometry>
        <box size="0.258 0.168 0.02"/>
      </geometry>
      <material name="chassis_mat"/>
    </visual>
    <collision>
      <origin xyz="0 0 -0.01"/>
      <geometry>
        <box size="0.258 0.168 0.02"/>
      </geometry>
    </collision>
    <inertial>
      <origin xyz="0 0 -0.01"/>
      <mass value="2.788"/>
      <inertia ixx="0.00665030933333" ixy="0" ixz="0" iyy="0.0155579693333" iyz="0" izz="0.022022412"/>
    </inertial>
  </link>
  <joint name="base_link_to_chasis" type="fixed">
    <parent link="base_link"/>
    <child link="chassis"/>
  </joint>
    <gazebo reference="chassis">
    <material>Gazebo/White</material>
  </gazebo>

  <!-- - - - - - - - - - - - - - - - - - - - - - - - - - - - - - - - - - - -->
  <!-- FRONT -->

  <!-- axel_carrier -->
  <!-- left -->
  <link name="left_front_axle_carrier">
    <inertial>
      <mass value="0.001"/>
      <inertia ixx="0.001" ixy="0" ixz="0" iyy="0.001" iyz="0" izz="0.001"/>
    </inertial>
  </link>
  <joint name="left_steering_joint" type="revolute">
    <parent link="chassis"/>
    <child link="left_front_axle_carrier"/>
    <origin xyz="0.1675 0.1525 -0.0235"/>
    <axis xyz="0 0 1"/>
    <limit effort="0.5649" lower="-0.785398163" upper="0.785398163" velocity="4.553"/>
  </joint>
  <transmission name="left_steering_trans">
    <type>transmission_interface/SimpleTransmission</type>
    <joint name="left_steering_joint">
      <hardwareInterface>hardware_interface/EffortJointInterface</hardwareInterface>
    </joint>
    <actuator name="left_steering_act">
      <mechanicalReduction>1</mechanicalReduction>
    </actuator>
  </transmission>
  <!-- right -->
  <link name="right_front_axle_carrier">
    <inertial>
      <mass value="0.001"/>
      <inertia ixx="0.001" ixy="0" ixz="0" iyy="0.001" iyz="0" izz="0.001"/>
    </inertial>
  </link>
  <joint name="right_steering_joint" type="revolute">
    <parent link="chassis"/>
    <child link="right_front_axle_carrier"/>
    <origin xyz="0.1675 -0.1525 -0.0235"/>
    <axis xyz="0 0 1"/>
    <limit effort="0.5649" lower="-0.785398163" upper="0.785398163" velocity="4.553"/>
  </joint>
  <transmission name="right_steering_trans">
    <type>transmission_interface/SimpleTransmission</type>
    <joint name="right_steering_joint">
      <hardwareInterface>hardware_interface/EffortJointInterface</hardwareInterface>
    </joint>
    <actuator name="right_steering_act">
      <mechanicalReduction>1</mechanicalReduction>
    </actuator>
  </transmission>
  

  <!-- wheel -->
  <!-- left -->
  <link name="left_front_wheel">
    <visual>
      <origin xyz="0                      -6.93889390391e-18                      0"/>
      <geometry>
        <cylinder length="0.0889" radius="0.073025"/>
      </geometry>
      <material name="tire_mat"/>
    </visual>
    <collision>
      <origin xyz="0                      -6.93889390391e-18                      0"/>
      <geometry>
        <cylinder length="0.0889" radius="0.073025"/>
      </geometry>
    </collision>
    <inertial>
      <mass value="0.29"/>
      <inertia ixx="0.000746465912979" ixy="0" ixz="0" iyy="0.000746465912979" iyz="0" izz="0.00111094334263"/>
    </inertial>
  </link>
  <joint name="left_front_axle" type="continuous">
    <parent link="left_front_axle_carrier"/>
    <child link="left_front_wheel"/>
    <origin rpy="1.57079633 0 0"/>
    <axis xyz="0 0 -1"/>
    <limit effort="5.12766" velocity="244.8696"/>
  </joint>
  <transmission name="left_front_axle_trans">
    <type>transmission_interface/SimpleTransmission</type>
    <joint name="left_front_axle">
      <hardwareInterface>hardware_interface/EffortJointInterface</hardwareInterface>
    </joint>
    <actuator name="left_front_axle_act">
      <mechanicalReduction>1</mechanicalReduction>
    </actuator>
  </transmission>
  <gazebo reference="left_front_wheel">
    <material>Gazebo/Black</material>
  </gazebo>
  <!-- right -->
  <link name="right_front_wheel">
    <visual>
      <origin xyz="0                      6.93889390391e-18                      0"/>
      <geometry>
        <cylinder length="0.0889" radius="0.073025"/>
      </geometry>
      <material name="tire_mat"/>
    </visual>
    <collision>
      <origin xyz="0                      6.93889390391e-18                      0"/>
      <geometry>
        <cylinder length="0.0889" radius="0.073025"/>
      </geometry>
    </collision>
    <inertial>
      <mass value="0.29"/>
      <inertia ixx="0.000746465912979" ixy="0" ixz="0" iyy="0.000746465912979" iyz="0" izz="0.00111094334263"/>
    </inertial>
  </link>
  <joint name="right_front_axle" type="continuous">
    <parent link="right_front_axle_carrier"/>
    <child link="right_front_wheel"/>
    <origin rpy="1.57079633 0 0"/>
    <axis xyz="0 0 -1"/>
    <limit effort="5.12766" velocity="244.8696"/>
  </joint>
  <transmission name="right_front_axle_trans">
    <type>transmission_interface/SimpleTransmission</type>
    <joint name="right_front_axle">
      <hardwareInterface>hardware_interface/EffortJointInterface</hardwareInterface>
    </joint>
    <actuator name="right_front_axle_act">
      <mechanicalReduction>1</mechanicalReduction>
    </actuator>
  </transmission>
  <gazebo reference="right_front_wheel">
    <material>Gazebo/Black</material>
  </gazebo>

  <!-- - - - - - - - - - - - - - - - - - - - - - - - - - - - - - - - - - - -->
  <!-- REAR -->

  <!-- wheels -->
  <!-- left -->
  <link name="left_rear_wheel">
    <visual>
      <origin xyz="0                      -6.93889390391e-18                      0"/>
      <geometry>
        <cylinder length="0.0889" radius="0.073025"/>
      </geometry>
      <material name="tire_mat"/>
    </visual>
    <collision>
      <origin xyz="0                      -6.93889390391e-18                      0"/>
      <geometry>
        <cylinder length="0.0889" radius="0.073025"/>
      </geometry>
    </collision>
    <inertial>
      <mass value="0.29"/>
      <inertia ixx="0.000746465912979" ixy="0" ixz="0" iyy="0.000746465912979" iyz="0" izz="0.00111094334263"/>
    </inertial>
  </link>
  <joint name="left_rear_axle" type="continuous">
    <parent link="chassis"/>
    <child link="left_rear_wheel"/>
    <origin xyz="-0.1675 0.1525 -0.0235" rpy="1.57079633 0 0"/>
    <axis xyz="0 0 -1"/>
    <limit effort="5.12766" velocity="244.8696"/>
  </joint>
  <transmission name="left_rear_axle_trans">
    <type>transmission_interface/SimpleTransmission</type>
    <joint name="left_rear_axle">
      <hardwareInterface>hardware_interface/EffortJointInterface</hardwareInterface>
    </joint>
    <actuator name="left_rear_axle_act">
      <mechanicalReduction>1</mechanicalReduction>
    </actuator>
  </transmission>
  <gazebo reference="left_rear_wheel">
    <material>Gazebo/Black</material>
  </gazebo>
  <!-- right -->
  <link name="right_rear_wheel">
    <visual>
      <origin xyz="0                      6.93889390391e-18                      0"/>
      <geometry>
        <cylinder length="0.0889" radius="0.073025"/>
      </geometry>
      <material name="tire_mat"/>
    </visual>
    <collision>
      <origin xyz="0                      6.93889390391e-18                      0"/>
      <geometry>
        <cylinder length="0.0889" radius="0.073025"/>
      </geometry>
    </collision>
    <inertial>
      <mass value="0.29"/>
      <inertia ixx="0.000746465912979" ixy="0" ixz="0" iyy="0.000746465912979" iyz="0" izz="0.00111094334263"/>
    </inertial>
  </link>
  <joint name="right_rear_axle" type="continuous">
    <parent link="chassis"/>
    <child link="right_rear_wheel"/>
    <origin xyz="-0.1675 -0.1525 -0.0235" rpy="1.57079633 0 0"/>
    <axis xyz="0 0 -1"/>
    <limit effort="5.12766" velocity="244.8696"/>
  </joint>
  <transmission name="right_rear_axle_trans">
    <type>transmission_interface/SimpleTransmission</type>
    <joint name="right_rear_axle">
      <hardwareInterface>hardware_interface/EffortJointInterface</hardwareInterface>
    </joint>
    <actuator name="right_rear_axle_act">
      <mechanicalReduction>1</mechanicalReduction>
    </actuator>
  </transmission>
  <gazebo reference="right_rear_wheel">
    <material>Gazebo/Black</material>
  </gazebo>

  <!-- gazebo plugins for control and odometry ground truth-->
  <gazebo>
    <plugin filename="libgazebo_ros_control.so" name="gazebo_ros_control"/>
    <plugin filename="libgazebo_ros_p3d.so" name="gazebo_ros_p3d">
      <frameName>map</frameName>
      <bodyName>base_link</bodyName>
      <topicName>odom_truth</topicName>
      <updateRate>30.0</updateRate>
    </plugin>
  </gazebo>
</robot>

